2023-03-13 14:25:55,594 ERROR: Exception on /user/test [GET] [in C:\Users\Nick\Documents\Praxisarbeit\praxisarbeit\lib\site-packages\flask\app.py:1741]
Traceback (most recent call last):
  File "C:\Users\Nick\Documents\Praxisarbeit\praxisarbeit\lib\site-packages\flask\app.py", line 2525, in wsgi_app
    response = self.full_dispatch_request()
  File "C:\Users\Nick\Documents\Praxisarbeit\praxisarbeit\lib\site-packages\flask\app.py", line 1822, in full_dispatch_request
    rv = self.handle_user_exception(e)
  File "C:\Users\Nick\Documents\Praxisarbeit\praxisarbeit\lib\site-packages\flask\app.py", line 1820, in full_dispatch_request
    rv = self.dispatch_request()
  File "C:\Users\Nick\Documents\Praxisarbeit\praxisarbeit\lib\site-packages\flask\app.py", line 1796, in dispatch_request
    return self.ensure_sync(self.view_functions[rule.endpoint])(**view_args)
  File "C:\Users\Nick\Documents\Praxisarbeit\praxisarbeit\lib\site-packages\flask_login\utils.py", line 290, in decorated_view
    return current_app.ensure_sync(func)(*args, **kwargs)
  File "C:\Users\Nick\Documents\Praxisarbeit\app\main\routes.py", line 221, in user
    page=page, per_page=certificates.config['CERTIFICATES_PER_PAGE'], error_out=False)
UnboundLocalError: local variable 'certificates' referenced before assignment
2023-03-13 14:28:23,729 INFO: Certificates startup [in C:\Users\Nick\Documents\Praxisarbeit\app\__init__.py:48]
2023-03-13 14:44:21,366 INFO: Certificates startup [in C:\Users\Nick\Documents\Praxisarbeit\app\__init__.py:51]
2023-03-13 14:56:58,768 INFO: Certificates startup [in C:\Users\Nick\Documents\Praxisarbeit\app\__init__.py:51]
2023-03-13 15:04:44,364 INFO: Certificates startup [in C:\Users\Nick\Documents\Praxisarbeit\app\__init__.py:51]
2023-03-13 15:12:10,103 INFO: Certificates startup [in C:\Users\Nick\Documents\Praxisarbeit\app\__init__.py:51]
2023-03-13 15:36:29,291 INFO: Certificates startup [in C:\Users\Nick\Documents\Praxisarbeit\app\__init__.py:51]
2023-03-13 15:40:17,928 INFO: Certificates startup [in C:\Users\Nick\Documents\Praxisarbeit\app\__init__.py:51]
2023-03-13 15:43:13,499 INFO: Certificates startup [in C:\Users\Nick\Documents\Praxisarbeit\app\__init__.py:51]
2023-03-13 15:49:33,582 INFO: Certificates startup [in C:\Users\Nick\Documents\Praxisarbeit\app\__init__.py:51]
2023-03-13 15:49:41,989 INFO: Certificates startup [in C:\Users\Nick\Documents\Praxisarbeit\app\__init__.py:51]
2023-03-13 15:49:45,628 INFO: Certificates startup [in C:\Users\Nick\Documents\Praxisarbeit\app\__init__.py:51]
2023-03-13 15:51:43,692 INFO: Certificates startup [in C:\Users\Nick\Documents\Praxisarbeit\app\__init__.py:51]
2023-03-13 16:21:27,312 INFO: Certificates startup [in C:\Users\Nick\Documents\Praxisarbeit\app\__init__.py:51]
2023-03-13 16:25:08,783 ERROR: Exception on /api/download/csr/mnfsdjnfsdjfsd.post.ch [GET] [in C:\Users\Nick\Documents\Praxisarbeit\praxisarbeit\lib\site-packages\flask\app.py:1741]
Traceback (most recent call last):
  File "C:\Users\Nick\Documents\Praxisarbeit\praxisarbeit\lib\site-packages\flask\app.py", line 2525, in wsgi_app
    response = self.full_dispatch_request()
  File "C:\Users\Nick\Documents\Praxisarbeit\praxisarbeit\lib\site-packages\flask\app.py", line 1822, in full_dispatch_request
    rv = self.handle_user_exception(e)
  File "C:\Users\Nick\Documents\Praxisarbeit\praxisarbeit\lib\site-packages\flask\app.py", line 1820, in full_dispatch_request
    rv = self.dispatch_request()
  File "C:\Users\Nick\Documents\Praxisarbeit\praxisarbeit\lib\site-packages\flask\app.py", line 1796, in dispatch_request
    return self.ensure_sync(self.view_functions[rule.endpoint])(**view_args)
  File "C:\Users\Nick\Documents\Praxisarbeit\praxisarbeit\lib\site-packages\flask_httpauth.py", line 172, in decorated
    return self.ensure_sync(f)(*args, **kwargs)
  File "C:\Users\Nick\Documents\Praxisarbeit\app\api\certificates.py", line 26, in get_certificate_csr
    certificate = Certificate.query.filter_by(cn=cn, user_id=g.current_user.id).first_or_404()
  File "C:\Users\Nick\Documents\Praxisarbeit\praxisarbeit\lib\site-packages\flask\ctx.py", line 52, in __getattr__
    raise AttributeError(name) from None
AttributeError: current_user
2023-03-13 16:26:09,009 ERROR: Exception on /api/download/key/mnfsdjnfsdjfsd.post.ch [GET] [in C:\Users\Nick\Documents\Praxisarbeit\praxisarbeit\lib\site-packages\flask\app.py:1741]
Traceback (most recent call last):
  File "C:\Users\Nick\Documents\Praxisarbeit\praxisarbeit\lib\site-packages\flask\app.py", line 2525, in wsgi_app
    response = self.full_dispatch_request()
  File "C:\Users\Nick\Documents\Praxisarbeit\praxisarbeit\lib\site-packages\flask\app.py", line 1822, in full_dispatch_request
    rv = self.handle_user_exception(e)
  File "C:\Users\Nick\Documents\Praxisarbeit\praxisarbeit\lib\site-packages\flask\app.py", line 1820, in full_dispatch_request
    rv = self.dispatch_request()
  File "C:\Users\Nick\Documents\Praxisarbeit\praxisarbeit\lib\site-packages\flask\app.py", line 1796, in dispatch_request
    return self.ensure_sync(self.view_functions[rule.endpoint])(**view_args)
  File "C:\Users\Nick\Documents\Praxisarbeit\praxisarbeit\lib\site-packages\flask_httpauth.py", line 172, in decorated
    return self.ensure_sync(f)(*args, **kwargs)
  File "C:\Users\Nick\Documents\Praxisarbeit\app\api\certificates.py", line 15, in get_certificate_key
    certificate = Certificate.query.filter_by(cn=cn, user_id=g.current_user.id).first_or_404()
  File "C:\Users\Nick\Documents\Praxisarbeit\praxisarbeit\lib\site-packages\flask\ctx.py", line 52, in __getattr__
    raise AttributeError(name) from None
AttributeError: current_user
2023-03-13 16:26:43,909 ERROR: Exception on /api/download/key/mnfsdjnfsdjfsd.post.ch [GET] [in C:\Users\Nick\Documents\Praxisarbeit\praxisarbeit\lib\site-packages\flask\app.py:1741]
Traceback (most recent call last):
  File "C:\Users\Nick\Documents\Praxisarbeit\praxisarbeit\lib\site-packages\flask\app.py", line 2525, in wsgi_app
    response = self.full_dispatch_request()
  File "C:\Users\Nick\Documents\Praxisarbeit\praxisarbeit\lib\site-packages\flask\app.py", line 1822, in full_dispatch_request
    rv = self.handle_user_exception(e)
  File "C:\Users\Nick\Documents\Praxisarbeit\praxisarbeit\lib\site-packages\flask\app.py", line 1820, in full_dispatch_request
    rv = self.dispatch_request()
  File "C:\Users\Nick\Documents\Praxisarbeit\praxisarbeit\lib\site-packages\flask\app.py", line 1796, in dispatch_request
    return self.ensure_sync(self.view_functions[rule.endpoint])(**view_args)
  File "C:\Users\Nick\Documents\Praxisarbeit\praxisarbeit\lib\site-packages\flask_httpauth.py", line 172, in decorated
    return self.ensure_sync(f)(*args, **kwargs)
  File "C:\Users\Nick\Documents\Praxisarbeit\app\api\certificates.py", line 15, in get_certificate_key
    certificate = Certificate.query.filter_by(cn=cn, user_id=g.current_user.id).first_or_404()
  File "C:\Users\Nick\Documents\Praxisarbeit\praxisarbeit\lib\site-packages\flask\ctx.py", line 52, in __getattr__
    raise AttributeError(name) from None
AttributeError: current_user
2023-03-13 16:28:55,671 ERROR: Exception on /api/download/pfx/nkdasndasd.pnet.chn [GET] [in C:\Users\Nick\Documents\Praxisarbeit\praxisarbeit\lib\site-packages\flask\app.py:1741]
Traceback (most recent call last):
  File "C:\Users\Nick\Documents\Praxisarbeit\praxisarbeit\lib\site-packages\flask\app.py", line 2525, in wsgi_app
    response = self.full_dispatch_request()
  File "C:\Users\Nick\Documents\Praxisarbeit\praxisarbeit\lib\site-packages\flask\app.py", line 1822, in full_dispatch_request
    rv = self.handle_user_exception(e)
  File "C:\Users\Nick\Documents\Praxisarbeit\praxisarbeit\lib\site-packages\flask\app.py", line 1820, in full_dispatch_request
    rv = self.dispatch_request()
  File "C:\Users\Nick\Documents\Praxisarbeit\praxisarbeit\lib\site-packages\flask\app.py", line 1796, in dispatch_request
    return self.ensure_sync(self.view_functions[rule.endpoint])(**view_args)
  File "C:\Users\Nick\Documents\Praxisarbeit\praxisarbeit\lib\site-packages\flask_httpauth.py", line 172, in decorated
    return self.ensure_sync(f)(*args, **kwargs)
  File "C:\Users\Nick\Documents\Praxisarbeit\app\api\certificates.py", line 37, in download_pfx
    cert = Certificate.query.filter_by(cn=cn, user_id=g.current_user.id).first_or_404()
  File "C:\Users\Nick\Documents\Praxisarbeit\praxisarbeit\lib\site-packages\flask\ctx.py", line 52, in __getattr__
    raise AttributeError(name) from None
AttributeError: current_user
2023-03-13 16:29:22,625 ERROR: Exception on /api/download/pfx/njnjnjn [GET] [in C:\Users\Nick\Documents\Praxisarbeit\praxisarbeit\lib\site-packages\flask\app.py:1741]
Traceback (most recent call last):
  File "C:\Users\Nick\Documents\Praxisarbeit\praxisarbeit\lib\site-packages\flask\app.py", line 2525, in wsgi_app
    response = self.full_dispatch_request()
  File "C:\Users\Nick\Documents\Praxisarbeit\praxisarbeit\lib\site-packages\flask\app.py", line 1822, in full_dispatch_request
    rv = self.handle_user_exception(e)
  File "C:\Users\Nick\Documents\Praxisarbeit\praxisarbeit\lib\site-packages\flask\app.py", line 1820, in full_dispatch_request
    rv = self.dispatch_request()
  File "C:\Users\Nick\Documents\Praxisarbeit\praxisarbeit\lib\site-packages\flask\app.py", line 1796, in dispatch_request
    return self.ensure_sync(self.view_functions[rule.endpoint])(**view_args)
  File "C:\Users\Nick\Documents\Praxisarbeit\praxisarbeit\lib\site-packages\flask_httpauth.py", line 172, in decorated
    return self.ensure_sync(f)(*args, **kwargs)
  File "C:\Users\Nick\Documents\Praxisarbeit\app\api\certificates.py", line 37, in download_pfx
    cert = Certificate.query.filter_by(cn=cn, user_id=g.current_user.id).first_or_404()
  File "C:\Users\Nick\Documents\Praxisarbeit\praxisarbeit\lib\site-packages\flask\ctx.py", line 52, in __getattr__
    raise AttributeError(name) from None
AttributeError: current_user
2023-03-13 16:59:41,767 INFO: Certificates startup [in C:\Users\Nick\Documents\Praxisarbeit\app\__init__.py:51]
